2024-09-19 22:01:06,467 - httpx - INFO - HTTP Request: POST https://api.telegram.org/botyour_telegram_bot_token_here/getMe "HTTP/1.1 404 Not Found"
Traceback (most recent call last):
  File "/home/runner/tgchatgptbot/.pythonlibs/lib/python3.11/site-packages/telegram/_bot.py", line 777, in initialize
    await self.get_me()
  File "/home/runner/tgchatgptbot/.pythonlibs/lib/python3.11/site-packages/telegram/ext/_extbot.py", line 1920, in get_me
    return await super().get_me(
           ^^^^^^^^^^^^^^^^^^^^^
  File "/home/runner/tgchatgptbot/.pythonlibs/lib/python3.11/site-packages/telegram/_bot.py", line 909, in get_me
    result = await self._post(
             ^^^^^^^^^^^^^^^^^
  File "/home/runner/tgchatgptbot/.pythonlibs/lib/python3.11/site-packages/telegram/_bot.py", line 623, in _post
    return await self._do_post(
           ^^^^^^^^^^^^^^^^^^^^
  File "/home/runner/tgchatgptbot/.pythonlibs/lib/python3.11/site-packages/telegram/ext/_extbot.py", line 355, in _do_post
    return await super()._do_post(
           ^^^^^^^^^^^^^^^^^^^^^^^
  File "/home/runner/tgchatgptbot/.pythonlibs/lib/python3.11/site-packages/telegram/_bot.py", line 652, in _do_post
    result = await request.post(
             ^^^^^^^^^^^^^^^^^^^
  File "/home/runner/tgchatgptbot/.pythonlibs/lib/python3.11/site-packages/telegram/request/_baserequest.py", line 201, in post
    result = await self._request_wrapper(
             ^^^^^^^^^^^^^^^^^^^^^^^^^^^^
  File "/home/runner/tgchatgptbot/.pythonlibs/lib/python3.11/site-packages/telegram/request/_baserequest.py", line 380, in _request_wrapper
    raise InvalidToken(message)
telegram.error.InvalidToken: Not Found

The above exception was the direct cause of the following exception:

Traceback (most recent call last):
  File "/home/runner/tgchatgptbot/main.py", line 17, in <module>
    bot.run()
  File "/home/runner/tgchatgptbot/bot/telegram_bot.py", line 23, in run
    self.application.run_polling(allowed_updates=Update.ALL_TYPES)
  File "/home/runner/tgchatgptbot/.pythonlibs/lib/python3.11/site-packages/telegram/ext/_application.py", line 881, in run_polling
    return self.__run(
           ^^^^^^^^^^^
  File "/home/runner/tgchatgptbot/.pythonlibs/lib/python3.11/site-packages/telegram/ext/_application.py", line 1079, in __run
    loop.run_until_complete(self.initialize())
  File "/nix/store/f98g7xbckgqbkagdvpzc2r6lv3h1p9ki-python3-3.11.9/lib/python3.11/asyncio/base_events.py", line 654, in run_until_complete
    return future.result()
           ^^^^^^^^^^^^^^^
  File "/home/runner/tgchatgptbot/.pythonlibs/lib/python3.11/site-packages/telegram/ext/_application.py", line 503, in initialize
    await self.bot.initialize()
  File "/home/runner/tgchatgptbot/.pythonlibs/lib/python3.11/site-packages/telegram/ext/_extbot.py", line 301, in initialize
    await super().initialize()
  File "/home/runner/tgchatgptbot/.pythonlibs/lib/python3.11/site-packages/telegram/_bot.py", line 779, in initialize
    raise InvalidToken(f"The token `{self._token}` was rejected by the server.") from exc
telegram.error.InvalidToken: The token `your_telegram_bot_token_here` was rejected by the server.